<?xml version='1.0'?>
<sdf version='1.3'>
  <model name="Omniwheel_EK">
    <link name='MainWheel'>
      <frame name="MainWheel_frame">
        <pose>0 0 0 0 0 0</pose>
      </frame>
      <collision name='collision'>
        <geometry>
          <cylinder>
            <radius> 0.034 </radius>
            <length> 0.013 </length>
          </cylinder>
        </geometry>
      </collision>
      <visual name='visual'>
        <geometry>
          <cylinder>
            <radius> 0.034 </radius>
            <length> 0.013 </length>
          </cylinder>
        </geometry>
      </visual>
    </link>

    <link name="axis">
      <pose> 0 0 -.025 0 0 0 </pose>
      <collision name='colision'>
        <geometry>
          <cylinder>
            <radius> 0.003175 </radius>
            <length> 0.050 </length>
          </cylinder>
        </geometry>
      </collision>
      <visual name='visual'>
        <geometry>
          <cylinder>
            <radius> 0.003175 </radius>
            <length> 0.050 </length>
          </cylinder>
        </geometry>
      </visual>
    </link>

    <link name="roller1">
      <!-- <frame name="MainWheel_frame"> -->
        <pose frame="roller1_frame">0.029 0 0 1.57 0 0</pose>
      <!-- </frame> -->
      <collision name="collision">
        <geometry>
          <cylinder>
            <radius>.006</radius>
            <length>.004</length>
          </cylinder>
        </geometry>
      </collision>
      <visual name="visual">
        <geometry>
          <cylinder>
            <radius>.006</radius>
            <length>.004</length>
          </cylinder>
        </geometry>
        <material>
          <ambient>0 0 1 1</ambient>
          <diffuse>0 0 1 1</diffuse>
          <specular>0.1 0.1 0.1 1</specular>
          <emissive>0 0 0 0</emissive>
        </material>
      </visual>
    </link>

    <link name="roller2">
      <pose frame="roller2_frame">0.02771 0.00855 0 1.57 0 0.2991</pose>
      <!-- <pose frame="roller2_frame">0.015 0 0 1.57 0 0</pose> -->
      <collision name="collision">
        <geometry>
          <cylinder>
            <radius>.006</radius>
            <length>.004</length>
          </cylinder>
        </geometry>
      </collision>
      <visual name="visual">
        <geometry>
          <cylinder>
            <radius>.006</radius>
            <length>.004</length>
          </cylinder>
        </geometry>
        <material>
          <ambient>0 0 1 1</ambient>
          <diffuse>0 0 1 1</diffuse>
          <specular>0.1 0.1 0.1 1</specular>
          <emissive>0 0 0 0</emissive>
        </material>
      </visual>
    </link>

    <link name="roller3">
      <pose frame="">0.02396 0.01634 0 1.57 0 0.5984</pose>
      <collision name="collision">
        <geometry>
          <cylinder>
            <radius>.006</radius>
            <length>.004</length>
          </cylinder>
        </geometry>
      </collision>
      <visual name="visual">
        <geometry>
          <cylinder>
            <radius>.006</radius>
            <length>.004</length>
          </cylinder>
        </geometry>
        <material>
          <ambient>1 0 0 1</ambient>
          <diffuse>1 0 0 1</diffuse>
          <specular>0.1 0.1 0.1 1</specular>
          <emissive>0 0 0 0</emissive>
        </material>
      </visual>
    </link>

    <link name="roller4">
      <pose>0.01808 0.02267 0 1.57 0 0.8976</pose>
      <collision name="collision">
        <geometry>
          <cylinder>
            <radius>.006</radius>
            <length>.004</length>
          </cylinder>
        </geometry>
      </collision>
      <visual name="visual">
        <geometry>
          <cylinder>
            <radius>.006</radius>
            <length>.004</length>
          </cylinder>
        </geometry>
        <material>
          <ambient>1 0 0 1</ambient>
          <diffuse>1 0 0 1</diffuse>
          <specular>0.1 0.1 0.1 1</specular>
          <emissive>0 0 0 0</emissive>
        </material>
      </visual>
    </link>

    <link name="roller5">
      <pose>0.01059 0.027 0 1.57 0 1.1968</pose>
      <collision name="collision">
        <geometry>
          <cylinder>
            <radius>.006</radius>
            <length>.004</length>
          </cylinder>
        </geometry>
      </collision>
      <visual name="visual">
        <geometry>
          <cylinder>
            <radius>.006</radius>
            <length>.004</length>
          </cylinder>
        </geometry>
        <material>
          <ambient>1 0 0 1</ambient>
          <diffuse>1 0 0 1</diffuse>
          <specular>0.1 0.1 0.1 1</specular>
          <emissive>0 0 0 0</emissive>
        </material>
      </visual>
    </link>

    <link name="roller6">
      <pose>0.00217 0.02892 0 1.57 0 1.496</pose>
      <collision name="collision">
        <geometry>
          <cylinder>
            <radius>.006</radius>
            <length>.004</length>
          </cylinder>
        </geometry>
      </collision>
      <visual name="visual">
        <geometry>
          <cylinder>
            <radius>.006</radius>
            <length>.004</length>
          </cylinder>
        </geometry>
        <material>
          <ambient>1 0 0 1</ambient>
          <diffuse>1 0 0 1</diffuse>
          <specular>0.1 0.1 0.1 1</specular>
          <emissive>0 0 0 0</emissive>
        </material>
      </visual>
    </link>

    <link name="roller7">
      <pose>-0.00645 0.02827 0 1.57 0 1.79520</pose>
      <collision name="collision">
        <geometry>
          <cylinder>
            <radius>.006</radius>
            <length>.004</length>
          </cylinder>
        </geometry>
      </collision>
      <visual name="visual">
        <geometry>
          <cylinder>
            <radius>.006</radius>
            <length>.004</length>
          </cylinder>
        </geometry>
        <material>
          <ambient>1 0 0 1</ambient>
          <diffuse>1 0 0 1</diffuse>
          <specular>0.1 0.1 0.1 1</specular>
          <emissive>0 0 0 0</emissive>
        </material>
      </visual>
    </link>

    <link name="roller8">
      <pose>-0.01450 0.02511 0 1.57 0 2.09440</pose>
      <collision name="collision">
        <geometry>
          <cylinder>
            <radius>.006</radius>
            <length>.004</length>
          </cylinder>
        </geometry>
      </collision>
      <visual name="visual">
        <geometry>
          <cylinder>
            <radius>.006</radius>
            <length>.004</length>
          </cylinder>
        </geometry>
        <material>
          <ambient>1 0 0 1</ambient>
          <diffuse>1 0 0 1</diffuse>
          <specular>0.1 0.1 0.1 1</specular>
          <emissive>0 0 0 0</emissive>
        </material>
      </visual>
    </link>

    <link name="roller9">
      <pose>-0.02126 0.01973 0 1.57 0 2.39359</pose>
      <collision name="collision">
        <geometry>
          <cylinder>
            <radius>.006</radius>
            <length>.004</length>
          </cylinder>
        </geometry>
      </collision>
      <visual name="visual">
        <geometry>
          <cylinder>
            <radius>.006</radius>
            <length>.004</length>
          </cylinder>
        </geometry>
        <material>
          <ambient>1 0 0 1</ambient>
          <diffuse>1 0 0 1</diffuse>
          <specular>0.1 0.1 0.1 1</specular>
          <emissive>0 0 0 0</emissive>
        </material>
      </visual>
    </link>

    <link name="roller10">
      <pose>-0.02613 0.01258 0 1.57 0 2.69279</pose>
      <collision name="collision">
        <geometry>
          <cylinder>
            <radius>.006</radius>
            <length>.004</length>
          </cylinder>
        </geometry>
      </collision>
      <visual name="visual">
        <geometry>
          <cylinder>
            <radius>.006</radius>
            <length>.004</length>
          </cylinder>
        </geometry>
        <material>
          <ambient>1 0 0 1</ambient>
          <diffuse>1 0 0 1</diffuse>
          <specular>0.1 0.1 0.1 1</specular>
          <emissive>0 0 0 0</emissive>
        </material>
      </visual>
    </link>

    <link name="roller11">
      <pose>-0.02868 0.00432 0 1.57 0 2.99199</pose>
      <collision name="collision">
        <geometry>
          <cylinder>
            <radius>.006</radius>
            <length>.004</length>
          </cylinder>
        </geometry>
      </collision>
      <visual name="visual">
        <geometry>
          <cylinder>
            <radius>.006</radius>
            <length>.004</length>
          </cylinder>
        </geometry>
        <material>
          <ambient>1 0 0 1</ambient>
          <diffuse>1 0 0 1</diffuse>
          <specular>0.1 0.1 0.1 1</specular>
          <emissive>0 0 0 0</emissive>
        </material>
      </visual>
    </link>

    <link name="roller12">
      <pose>-0.02868 -0.00432 0 1.57 0 3.29119</pose>
      <collision name="collision">
        <geometry>
          <cylinder>
            <radius>.006</radius>
            <length>.004</length>
          </cylinder>
        </geometry>
      </collision>
      <visual name="visual">
        <geometry>
          <cylinder>
            <radius>.006</radius>
            <length>.004</length>
          </cylinder>
        </geometry>
        <material>
          <ambient>1 0 0 1</ambient>
          <diffuse>1 0 0 1</diffuse>
          <specular>0.1 0.1 0.1 1</specular>
          <emissive>0 0 0 0</emissive>
        </material>
      </visual>
    </link>

    <link name="roller13">
      <pose>-0.02613 -0.01258 0 1.57 0 3.59039</pose>
      <collision name="collision">
        <geometry>
          <cylinder>
            <radius>.006</radius>
            <length>.004</length>
          </cylinder>
        </geometry>
      </collision>
      <visual name="visual">
        <geometry>
          <cylinder>
            <radius>.006</radius>
            <length>.004</length>
          </cylinder>
        </geometry>
        <material>
          <ambient>1 0 0 1</ambient>
          <diffuse>1 0 0 1</diffuse>
          <specular>0.1 0.1 0.1 1</specular>
          <emissive>0 0 0 0</emissive>
        </material>
      </visual>
    </link>

    <link name="roller14">
      <pose>-0.02126 -0.01973 0 1.57 0 3.88959</pose>
      <collision name="collision">
        <geometry>
          <cylinder>
            <radius>.006</radius>
            <length>.004</length>
          </cylinder>
        </geometry>
      </collision>
      <visual name="visual">
        <geometry>
          <cylinder>
            <radius>.006</radius>
            <length>.004</length>
          </cylinder>
        </geometry>
        <material>
          <ambient>1 0 0 1</ambient>
          <diffuse>1 0 0 1</diffuse>
          <specular>0.1 0.1 0.1 1</specular>
          <emissive>0 0 0 0</emissive>
        </material>
      </visual>
    </link>

    <link name="roller15">
      <pose>-0.01450 -0.02511 0 1.57 0 4.18879</pose>
      <collision name="collision">
        <geometry>
          <cylinder>
            <radius>.006</radius>
            <length>.004</length>
          </cylinder>
        </geometry>
      </collision>
      <visual name="visual">
        <geometry>
          <cylinder>
            <radius>.006</radius>
            <length>.004</length>
          </cylinder>
        </geometry>
        <material>
          <ambient>0 1 0 1</ambient>
          <diffuse>0 1 0 1</diffuse>
          <specular>0.1 0.1 0.1 1</specular>
          <emissive>0 0 0 0</emissive>
        </material>
      </visual>
    </link>

    <link name="roller16">
      <pose>-0.00645 -0.02827 0 1.57 0 4.48799</pose>
      <collision name="collision">
        <geometry>
          <cylinder>
            <radius>.006</radius>
            <length>.004</length>
          </cylinder>
        </geometry>
      </collision>
      <visual name="visual">
        <geometry>
          <cylinder>
            <radius>.006</radius>
            <length>.004</length>
          </cylinder>
        </geometry>
        <material>
          <ambient>1 0 0 1</ambient>
          <diffuse>1 0 0 1</diffuse>
          <specular>0.1 0.1 0.1 1</specular>
          <emissive>0 0 0 0</emissive>
        </material>
      </visual>
    </link>

    <link name="roller17">
      <pose>0.00217 -0.02892 0 1.57 0 4.78719</pose>
      <collision name="collision">
        <geometry>
          <cylinder>
            <radius>.006</radius>
            <length>.004</length>
          </cylinder>
        </geometry>
      </collision>
      <visual name="visual">
        <geometry>
          <cylinder>
            <radius>.006</radius>
            <length>.004</length>
          </cylinder>
        </geometry>
        <material>
          <ambient>1 0 0 1</ambient>
          <diffuse>1 0 0 1</diffuse>
          <specular>0.1 0.1 0.1 1</specular>
          <emissive>0 0 0 0</emissive>
        </material>
      </visual>
    </link>

    <link name="roller18">
      <pose>0.01059 -0.027 0 1.57 0 5.08639</pose>
      <collision name="collision">
        <geometry>
          <cylinder>
            <radius>.006</radius>
            <length>.004</length>
          </cylinder>
        </geometry>
      </collision>
      <visual name="visual">
        <geometry>
          <cylinder>
            <radius>.006</radius>
            <length>.004</length>
          </cylinder>
        </geometry>
        <material>
          <ambient>1 0 0 1</ambient>
          <diffuse>1 0 0 1</diffuse>
          <specular>0.1 0.1 0.1 1</specular>
          <emissive>0 0 0 0</emissive>
        </material>
      </visual>
    </link>

    <link name="roller19">
      <pose>0.01808 -0.02267 0 1.57 0 5.38559</pose>
      <collision name="collision">
        <geometry>
          <cylinder>
            <radius>.006</radius>
            <length>.004</length>
          </cylinder>
        </geometry>
      </collision>
      <visual name="visual">
        <geometry>
          <cylinder>
            <radius>.006</radius>
            <length>.004</length>
          </cylinder>
        </geometry>
        <material>
          <ambient>1 0 0 1</ambient>
          <diffuse>1 0 0 1</diffuse>
          <specular>0.1 0.1 0.1 1</specular>
          <emissive>0 0 0 0</emissive>
        </material>
      </visual>
    </link>    

    <link name="roller20">
      <pose>0.02396 -0.01634 0 1.57 0 5.68479</pose>
      <collision name="collision">
        <geometry>
          <cylinder>
            <radius>.006</radius>
            <length>.004</length>
          </cylinder>
        </geometry>
      </collision>
      <visual name="visual">
        <geometry>
          <cylinder>
            <radius>.006</radius>
            <length>.004</length>
          </cylinder>
        </geometry>
        <material>
          <ambient>1 0 0 1</ambient>
          <diffuse>1 0 0 1</diffuse>
          <specular>0.1 0.1 0.1 1</specular>
          <emissive>0 0 0 0</emissive>
        </material>
      </visual>
    </link>

    <link name="roller21">
      <pose>0.02771 -0.00855 0 1.57 0 5.98399</pose>
      <collision name="collision">
        <geometry>
          <cylinder>
            <radius>.006</radius>
            <length>.004</length>
          </cylinder>
        </geometry>
      </collision>
      <visual name="visual">
        <geometry>
          <cylinder>
            <radius>.006</radius>
            <length>.004</length>
          </cylinder>
        </geometry>
        <material>
          <ambient>1 0 0 1</ambient>
          <diffuse>1 0 0 1</diffuse>
          <specular>0.1 0.1 0.1 1</specular>
          <emissive>0 0 0 0</emissive>
        </material>
      </visual>
    </link>

    <joint type="revolute" name="roller1_hinge">
      <pose frame=''> 0 0 0 0 0 0 </pose>
      <child>roller1</child>
      <parent>MainWheel</parent>
      <axis>
          <xyz>0 0 1</xyz>
          <use_parent_model_frame>0</use_parent_model_frame>
          <limit>
            <lower>-1e+16</lower>
            <upper>1e+16</upper>
          </limit>
        </axis>
    </joint>

    <joint type="revolute" name="roller2_hinge">
      <parent>MainWheel</parent>
      <child>roller2</child>
      <pose> 0 0 0 0 0 0 </pose>
      <axis>
          <xyz>0 0 1</xyz>
          <use_parent_model_frame>0</use_parent_model_frame>
          <limit>
            <lower>-1e+16</lower>
            <upper>1e+16</upper>
          </limit>
      </axis>
    </joint>

    <joint type="revolute" name="roller3_hinge">
        <pose frame=''> 0 0 0 0 0 0 </pose>
      <child>roller3</child>
      <parent>MainWheel</parent>
      <axis>
          <xyz>0 0 1</xyz>
          <use_parent_model_frame>0</use_parent_model_frame>
          <limit>
            <lower>-1e+16</lower>
            <upper>1e+16</upper>
          </limit>
        </axis>
    </joint>

    <joint type="revolute" name="roller4_hinge">
        <pose> 0 0 0 0 0 0 </pose>
      <child>roller4</child>
      <parent>MainWheel</parent>
      <axis>
          <xyz>0 0 1</xyz>
          <use_parent_model_frame>0</use_parent_model_frame>
          <limit>
            <lower>-1e+16</lower>
            <upper>1e+16</upper>
          </limit>
        </axis>
    </joint>

    <joint type="revolute" name="roller5_hinge">
        <pose> 0 0 0 0 0 0 </pose>
      <child>roller5</child>
      <parent>MainWheel</parent>
      <axis>
          <xyz>0 0 1</xyz>
          <use_parent_model_frame>0</use_parent_model_frame>
          <limit>
            <lower>-1e+16</lower>
            <upper>1e+16</upper>
          </limit>
        </axis>
    </joint>

    <joint type="revolute" name="roller6_hinge">
        <pose> 0 0 0 0 0 0 </pose>
      <child>roller6</child>
      <parent>MainWheel</parent>
      <axis>
          <xyz>0 0 1</xyz>
          <use_parent_model_frame>0</use_parent_model_frame>
          <limit>
            <lower>-1e+16</lower>
            <upper>1e+16</upper>
          </limit>
        </axis>
    </joint>

    <joint type="revolute" name="roller7_hinge">
        <pose> 0 0 0 0 0 0 </pose>
      <child>roller7</child>
      <parent>MainWheel</parent>
      <axis>
          <xyz>0 0 1</xyz>
          <use_parent_model_frame>0</use_parent_model_frame>
          <limit>
            <lower>-1e+16</lower>
            <upper>1e+16</upper>
          </limit>
        </axis>
    </joint>

    <joint type="revolute" name="roller8_hinge">
        <pose> 0 0 0 0 0 0.0 </pose>
      <child>roller8</child>
      <parent>MainWheel</parent>
      <axis>
          <xyz>0 0 1</xyz>
          <use_parent_model_frame>0</use_parent_model_frame>
          <limit>
            <lower>-1e+16</lower>
            <upper>1e+16</upper>
          </limit>
        </axis>
    </joint>

    <joint type="revolute" name="roller9_hinge">
        <pose> 0 0 0 0 0 0.0 </pose>
      <child>roller9</child>
      <parent>MainWheel</parent>
      <axis>
          <xyz>0 0 1</xyz>
          <use_parent_model_frame>0</use_parent_model_frame>
          <limit>
            <lower>-1e+16</lower>
            <upper>1e+16</upper>
          </limit>
        </axis>
    </joint>

    <joint type="revolute" name="roller10_hinge">
        <pose> 0 0 0 0 0 0.0 </pose>
      <child>roller10</child>
      <parent>MainWheel</parent>
      <axis>
          <xyz>0 0 1</xyz>
          <use_parent_model_frame>0</use_parent_model_frame>
          <limit>
            <lower>-1e+16</lower>
            <upper>1e+16</upper>
          </limit>
        </axis>
    </joint>

    <joint type="revolute" name="roller11_hinge">
        <pose> 0 0 0 0 0 0.0 </pose>
      <child>roller11</child>
      <parent>MainWheel</parent>
      <axis>
          <xyz>0 0 1</xyz>
          <use_parent_model_frame>0</use_parent_model_frame>
          <limit>
            <lower>-1e+16</lower>
            <upper>1e+16</upper>
          </limit>
        </axis>
    </joint>

    <joint type="revolute" name="roller12_hinge">
        <pose> 0 0 0 0 0 0.00 </pose>
      <child>roller12</child>
      <parent>MainWheel</parent>
      <axis>
          <xyz>0 0 1</xyz>
          <use_parent_model_frame>0</use_parent_model_frame>
          <limit>
            <lower>-1e+16</lower>
            <upper>1e+16</upper>
          </limit>
        </axis>
    </joint>

    <joint type="revolute" name="roller13_hinge">
        <pose> 0 0 0 0 0 0.0 </pose>
      <child>roller13</child>
      <parent>MainWheel</parent>
      <axis>
          <xyz>0 0 1</xyz>
          <use_parent_model_frame>0</use_parent_model_frame>
          <limit>
            <lower>-1e+16</lower>
            <upper>1e+16</upper>
          </limit>
        </axis>
    </joint>

    <joint type="revolute" name="roller14_hinge">
        <pose> 0 0 0 0 0 0.0 </pose>
      <child>roller14</child>
      <parent>MainWheel</parent>
      <axis>
          <xyz>0 0 1</xyz>
          <use_parent_model_frame>0</use_parent_model_frame>
          <limit>
            <lower>-1e+16</lower>
            <upper>1e+16</upper>
          </limit>
        </axis>
    </joint>

    <joint type="revolute" name="roller15_hinge">
        <pose> 0 0 0 0 0 0.0 </pose>
      <child>roller15</child>
      <parent>MainWheel</parent>
      <axis>
          <xyz>0 0 1</xyz>
          <use_parent_model_frame>0</use_parent_model_frame>
          <limit>
            <lower>-1e+16</lower>
            <upper>1e+16</upper>
          </limit>
        </axis>
    </joint>

    <joint type="revolute" name="roller16_hinge">
        <pose> 0 0 0 0 0 0.0 </pose>
      <child>roller16</child>
      <parent>MainWheel</parent>
      <axis>
          <xyz>0 0 1</xyz>
          <use_parent_model_frame>0</use_parent_model_frame>
          <limit>
            <lower>-1e+16</lower>
            <upper>1e+16</upper>
          </limit>
        </axis>
    </joint>

    <joint type="revolute" name="roller17_hinge">
        <pose> 0 0 0 0 0 0.0 </pose>
      <child>roller17</child>
      <parent>MainWheel</parent>
      <axis>
          <xyz>0 0 1</xyz>
          <use_parent_model_frame>0</use_parent_model_frame>
          <limit>
            <lower>-1e+16</lower>
            <upper>1e+16</upper>
          </limit>
        </axis>
    </joint>

    <joint type="revolute" name="roller18_hinge">
        <pose> 0 0 0 0 0 0.0 </pose>
      <child>roller18</child>
      <parent>MainWheel</parent>
      <axis>
          <xyz>0 0 1</xyz>
          <use_parent_model_frame>0</use_parent_model_frame>
          <limit>
            <lower>-1e+16</lower>
            <upper>1e+16</upper>
          </limit>
        </axis>
    </joint>

    <joint type="revolute" name="roller19_hinge">
        <pose> 0 0 0 0 0 0.0 </pose>
      <child>roller19</child>
      <parent>MainWheel</parent>
      <axis>
          <xyz>0 0 1</xyz>
          <use_parent_model_frame>0</use_parent_model_frame>
          <limit>
            <lower>-1e+16</lower>
            <upper>1e+16</upper>
          </limit>
        </axis>
    </joint>

    <joint type="revolute" name="roller20_hinge">
        <pose> 0 0 0 0 0 0.0 </pose>
      <child>roller20</child>
      <parent>MainWheel</parent>
      <axis>
          <xyz>0 0 1</xyz>
          <use_parent_model_frame>0</use_parent_model_frame>
          <limit>
            <lower>-1e+16</lower>
            <upper>1e+16</upper>
          </limit>
        </axis>
    </joint>

    <joint type="revolute" name="roller21_hinge">
        <pose> 0 0 0 0 0 0.0 </pose>
      <child>roller21</child>
      <parent>MainWheel</parent>
      <axis>
          <xyz>0 0 1</xyz>
          <use_parent_model_frame>0</use_parent_model_frame>
          <limit>
            <lower>-1e+16</lower>
            <upper>1e+16</upper>
          </limit>
        </axis>
    </joint> 

    <joint type="fixed" name="mainAxis">
      <pose> 0 0 0 0 0 0 </pose>
      <child> axis </child>
      <parent>MainWheel </parent>
      <axis>
        <xyz> 0 0 1 </xyz>
      </axis>
    </joint>


  </model>
</sdf>